<?xml version="1.0"?>

<robot xmlns:xacro="http://www.ros.org/wiki/xacro">


	<!-- Things that are needed only for Gazebo (not the physical robot). These include sensor and controller plugin specifications -->
	<xacro:include filename="$(find hyl_description)/urdfs/leg/leg.transmission.xacro"/>
	<xacro:include filename="$(find hyl_description)/urdfs/leg/leg.gazebo.xacro"/>


	<!-- ================================== Leg ================================== -->
	<!-- The xacro macro xacro:hyl_leg contains: slider upper and lower leg -->
	<xacro:macro name="hyl_leg" params="parent *origin load_force_sensors">

		<!-- Joints -->
		<!-- Slider joint -->
		<joint name="slider_joint" type="prismatic">
			<insert_block name="origin"/>
			<parent link="${parent}"/>
			<child  link="trunk"/>
			<limit effort="0.0" velocity="100.0" lower="-0.60" upper="0.5"/>
			<axis xyz="0 0 1"/>
			<dynamics damping="0" friction="0" />
		</joint>
		<!-- Hip assembly joint -->
		<joint name="haa_joint" type="fixed">
			<origin xyz="0 ${d_lr/2} 0" rpy="0 ${PI/2} ${PI}"/> 
			<parent link="trunk"/>
			<child  link="hipassembly"/>
		</joint>
		<!-- Upper leg joint -->
		<joint name="hfe_joint" type="revolute">
			<origin xyz="${d_p0p1} 0 0" rpy="${PI/2} 0 0"/>
			<parent link="hipassembly"/>
			<child  link="upperleg"/>
			<limit effort="150.0" velocity="12.0" lower="${-10*PI/36}"
				   upper="${14*PI/36}"/>
			<axis xyz="0 0 1"/>
			<dynamics damping="0" friction="0" />
			<safety_controller k_position="100" k_velocity="100" soft_lower_limit="${-10*PI/36}" soft_upper_limit="${14*PI/36}" />
		</joint>
		<!-- Lower leg joint -->
		<joint name="kfe_joint" type="revolute">
			<origin xyz="${d_p1p2} 0 0" rpy="0 0 0"/>
			<parent link="upperleg"/>
			<child  link="lowerleg"/>
			<limit effort="150.0" velocity="12.0" lower="${-14*PI/18}"
				   upper="${-2*PI/18}"/>
			<axis xyz="0 0 1"/>
			<dynamics damping="0" friction="0" />
			<safety_controller k_position="100" k_velocity="100" soft_lower_limit="${-14*PI/18}" soft_upper_limit="${-2*PI/18}" />
		</joint>
		<!-- Foot joint -->
		<joint name="foot_joint" type="fixed">
			<origin xyz="${d_p2p3} 0 0" rpy="${PI/2} 0 ${-PI/2}"/>
			<parent link="lowerleg"/>
			<child  link="foot"/>
		</joint>


		<!-- Links -->
		<!-- Trunk link -->
		<link name="trunk">
			<inertial>
				<origin xyz="${xcom_trunk} ${ycom_trunk} ${zcom_trunk}"/>
				<mass value="${m_trunk}"/>
				<inertia ixx="${ixx_trunk}" iyy="${iyy_trunk}" izz="${izz_trunk}"
						 ixy="${ixy_trunk}" ixz="${ixz_trunk}" iyz="${iyz_trunk}"/>
			</inertial>
			<visual>
				<origin xyz="0 0 0" rpy="-${PI/2} ${PI} 0"/>
				<geometry>
					<mesh filename="package://hyl_description/meshes/leg/trunk.dae" scale="1 1 1"/>
				</geometry>
			</visual>
			<collision>
				<origin xyz="0 0 0" rpy="-${PI/2} ${PI} 0"/>
				<geometry>
					<mesh filename="package://hyl_description/meshes/leg/trunk.dae" scale="1 1 1"/>
				</geometry>
			</collision>
		</link>
		<!-- Hip assembly link -->
		<link name="hipassembly">
			<inertial>
				<origin xyz="${xcom_hipassembly} ${ycom_hipassembly} ${zcom_hipassembly}"/>
				<mass value="${m_hipassembly}"/>
				<inertia ixx="${ixx_hipassembly}" iyy="${iyy_hipassembly}" izz="${izz_hipassembly}"
						 ixy="${ixy_hipassembly}" ixz="${ixz_hipassembly}" iyz="${iyz_hipassembly}"/>
			</inertial>
			<visual>
				<origin xyz="0 0 0" rpy="0 0 0"/>
				<geometry>
					<mesh filename="package://hyl_description/meshes/leg/hipassembly.dae" scale="1 1 1"/>
				</geometry>
			</visual>
			<collision>
				<origin xyz="0 0 0" rpy="0 0 0"/>
				<geometry>
					<mesh filename="package://hyl_description/meshes/leg/hipassembly.dae" scale="1 1 1"/>
				</geometry>
			</collision>
		</link>
		<!-- Upper leg link -->
		<link name="upperleg">
			<inertial>
				<origin xyz="${xcom_upperleg} ${ycom_upperleg} ${zcom_upperleg}"/>
				<mass value="${m_upperleg}"/>
				<inertia ixx="${ixx_upperleg}" iyy="${iyy_upperleg}" izz="${izz_upperleg}"
						 ixy="${ixy_upperleg}" ixz="${ixz_upperleg}" iyz="${iyz_upperleg}"/>
			</inertial>
			<visual> 
				<origin xyz="0 0 0" rpy="0 0 0"/>
				<geometry>
					<mesh filename="package://hyl_description/meshes/leg/upperleg.dae" scale="1 1 1"/>
				</geometry>
			</visual>
			<collision>
				<origin xyz="0 0 0" rpy="0 0 0"/>
				<geometry>
					<mesh filename="package://hyl_description/meshes/leg/upperleg.dae" scale="1 1 1"/>
				</geometry>
			</collision>
		</link>
		<!-- Lower leg link -->
		<link name="lowerleg">
			<inertial>
				<origin xyz="${xcom_lowerleg} ${ycom_lowerleg} ${zcom_lowerleg}"/>
				<mass value="${m_lowerleg}"/>
				<inertia ixx="${ixx_lowerleg}" iyy="${iyy_lowerleg}" izz="${izz_lowerleg}"
						 ixy="${ixy_lowerleg}" ixz="${ixz_lowerleg}" iyz="${iyz_lowerleg}"/>
			</inertial>
			<visual>
				<geometry>
					<mesh filename="package://hyl_description/meshes/leg/lowerleg.dae" scale="1 1 1"/>
				</geometry>
				<material name="white"/>
			</visual>
			<collision>
				<geometry>
					<mesh filename="package://hyl_description/meshes/leg/lowerleg.dae" scale="1 1 1"/>
				</geometry>
			</collision>
		</link>
		<!-- Foot link -->
		<link name="foot">
			<inertial>
				<origin xyz="0 0 0"/>
				<mass value="0.01"/>
				<inertia ixx="0.0" iyy="0.0" izz="0.0" ixy="0.0" ixz="0.0" iyz="0.0"/>
			</inertial>
			<collision>
				<origin xyz="0 0 0" rpy="0 0 0"/>
				<geometry>
					<sphere radius="0.02185"/>
				</geometry>
			</collision>
		</link>
		
		<!-- Extensions -->
		<xacro:leg_transmission/>
		<xacro:leg_gazebo load_force_sensors="${load_force_sensors}"/>
	</xacro:macro>

</robot>
